Workbook

Sheet Cham_diem
A1: STT | B1: Nguon_ZH | C1: Tham_chieu_VI | D1: Ban_dich_He_A | E1: Ban_dich_He_B | F1: Nguoi_cham_chinh | G1: Diem_A_chinh | H1: Diem_B_chinh | I1: Nguoi_cham_cheo | J1: Diem_A_cheo | K1: Diem_B_cheo | L1: Ghi_chu_A (chính+chéo) | M1: Ghi_chu_B (chính+chéo) | N1: Ghi_chu_chung | O1: Diem_A_final | P1: Diem_B_final | Q1: Ket_luan_AI | R1: Ghi_chu_bo_sung
A2: 1 | B2: =Du_lieu_goc!C3 -> 在遭受新冠肺炎疫情不小影响的背景下，2022年对越南恢复和发展经济具有重要意义。 | C2: =Du_lieu_goc!D3 -> Năm 2022 là năm có ý nghĩa quan trọng trong phục hồi và phát triển kinh tế Việt Nam sau những tác động của dịch COVID - 19. | D2: Trong bối cảnh chịu ảnh hưởng không nhỏ từ đại dịch COVID-19, năm 2022 có ý nghĩa quan trọng đối với sự phục hồi và phát triển kinh tế của Việt Nam. | E2: Trong bối cảnh ảnh hưởng nặng nề của dịch bệnh Covid-19, năm 2022 có ý nghĩa rất lớn đối với sự phục hồi và phát triển kinh tế của Việt Nam. | F2: Người 1 | G2: 95 | H2: 90 | I2: Người 2 | J2: 90 | K2: 78 | O2: 92 | P2: 84 | Q2: Hai người chấm lệch nhẹ (12 điểm).
A3: 2 | B3: =Du_lieu_goc!C4 -> 与新冠肺炎病毒共处不仅是医疗卫生问题，而且还涉及国家经济及社会所有活动的运作方式。 | C3: =Du_lieu_goc!D4 -> Sống chung với dịch COVID-19 không chỉ là vấn đề về y tế mà còn liên quan tới cả cách thức vận hành nền kinh tế và mọi hoạt động của xã hội. | D3: Việc chung sống với virus SARS-CoV-2 không chỉ là vấn đề y tế công cộng mà còn liên quan đến cách thức vận hành của nền kinh tế quốc gia và mọi hoạt động xã hội. | E3: Sống chung với Covid-19 không chỉ là vấn đề y tế, sức khỏe mà còn liên quan đến cách thức vận hành của mọi hoạt động kinh tế, xã hội của đất nước. | F3: Người 1 | G3: 90 | H3: 88 | I3: Người 2 | J3: 90 | K3: 84 | O3: 90 | P3: 86 | Q3: Hai người chấm thống nhất cao.
A4: 3 | B4: =Du_lieu_goc!C5 -> 为使经济尽可能早地恢复并可持续发展，同塔省国会代表黎明欢表示，应考虑经济自主性，制定政策提高经济主动性、抵御力和自主性。 | C4: =Du_lieu_goc!D5 -> Để nền kinh tế phát triển ổn định, sớm phục hồi, đại biểu Lê Minh Hoan, đoàn đại biểu Quốc hội tỉnh Đồng Tháp, cho rằng cần xem xét đến tính tự chủ của nền kinh tế, có chính sách nâng cao sức chủ động, sức chống chịu, tính tự chủ của nền kinh tế. | D4: Để nền kinh tế phục hồi và phát triển bền vững trong thời gian sớm nhất, đại biểu Quốc hội tỉnh Đồng Tháp Lê Minh Hoan cho rằng cần xem xét tính tự chủ của nền kinh tế, xây dựng các chính sách nâng cao tính chủ động, khả năng chống chịu và tự chủ của nền kinh tế. | E4: Để nền kinh tế phục hồi và phát triển bền vững trong thời gian sớm nhất, ông Leong Huân, đại diện Quốc hội tỉnh Đồng Tháp cho rằng, cần xem xét tự chủ kinh tế và xây dựng chính sách nâng cao tính chủ động, tự cường, tự chủ về kinh tế. | F4: Người 1 | G4: 90 | H4: 55 | I4: Người 2 | J4: 90 | K4: 45 | M4: Sai tên Lê Minh Hoan thành “Leong Huân”, làm sai người đưa ra nhận định. | O4: 90 | P4: 50 | Q4: Hai người chấm lệch nhẹ (10 điểm). A vượt B rõ rệt (90 vs 50). Ghi nhận lỗi: B: Sai tên Lê Minh Hoan thành “Leong Huân”, làm sai người đưa ra nhận định. Điểm thấp — nên kiểm tra thủ công trước khi đưa vào tính tương quan.
A5: 4 | B5: =Du_lieu_goc!C6 -> 尽早恢复经济、与病毒安全共处 | C5: =Du_lieu_goc!D6 -> Sớm phục hồi kinh tế, sống chung an toàn với dịch COVID - 19 | D5: Sớm phục hồi kinh tế, chung sống an toàn với virus | E5: Khôi phục nền kinh tế càng sớm càng tốt và chung sống an toàn với virus | F5: Người 1 | G5: 88 | H5: 85 | I5: Người 2 | J5: 96 | K5: 95 | O5: 92 | P5: 90 | Q5: Hai người chấm lệch nhẹ (10 điểm). A và B tương đương (92 vs 90).
A6: 5 | B6: =Du_lieu_goc!C7 -> 此外，进出口还实现了正增长。 | C6: =Du_lieu_goc!D7 -> Ngoài ra, một số tín hiệu về xuất nhập khẩu vẫn tăng trưởng. | D6: Ngoài ra, xuất nhập khẩu cũng đạt mức tăng trưởng dương. | E6: Ngoài ra, xuất nhập khẩu cũng đạt mức tăng trưởng tích cực. | F6: Người 1 | G6: 92 | H6: 88 | I6: Người 2 | J6: 90 | K6: 86 | O6: 91 | P6: 87 | Q6: Hai người chấm thống nhất cao.
A7: 6 | B7: =Du_lieu_goc!C8 -> 国会将就此颁布更详细的新决议。 | C7: =Du_lieu_goc!D8 -> Chắc chắn Quốc hội sẽ ban hành Nghị quyết nói rõ vấn đề này. | D7: Quốc hội sẽ ban hành một nghị quyết chi tiết hơn về vấn đề này. | E7: Quốc hội sẽ ban hành nghị quyết mới chi tiết hơn về vấn đề này. | F7: Người 1 | G7: 92 | H7: 93 | I7: Người 2 | J7: 85 | K7: 88 | M7: [Thắc mắc gốc] mới → [Đối chiếu bản Trung] B có "mới" (khớp 新决议 trong bản Trung), A thiếu — B chính xác hơn ở điểm này. | O7: 88 | P7: 90 | Q7: Hai người chấm lệch nhẹ (7 điểm). A và B tương đương (88 vs 90). Ghi nhận lỗi: A: mới
A8: 7 | B8: =Du_lieu_goc!C9 -> 防疫工作的方针是安全、灵活适应和有效防控，先决条件是提高疫苗覆盖率。 | C8: =Du_lieu_goc!D9 -> Về phòng chống dịch, cần đặt trọng tâm vào chủ trương thích ứng an toàn, linh hoạt và có hiệu quả với dịch bệnh, điều kiện tiên quyết là bao phủ vaccine. | D8: Phương châm công tác phòng chống dịch là an toàn, linh hoạt thích ứng và kiểm soát hiệu quả, điều kiện tiên quyết là nâng cao tỷ lệ bao phủ vắc-xin. | E8: Phương châm của công tác phòng chống dịch bệnh là an toàn, thích ứng linh hoạt, phòng ngừa và kiểm soát hiệu quả, điều kiện tiên quyết là tăng cường độ bao phủ vắc xin. | F8: Người 1 | G8: 93 | H8: 88 | I8: Người 2 | J8: 90 | K8: 88 | M8: [Thắc mắc gốc] phòng ngừa → [Đối chiếu bản Trung] B tách "phòng ngừa và kiểm soát" sát với 防控 hơn; A gộp thành "kiểm soát". | O8: 92 | P8: 88 | Q8: Hai người chấm thống nhất cao. Ghi nhận lỗi: A: phòng ngừa
A9: 8 | B9: =Du_lieu_goc!C10 -> 越南不能一直封闭，要重新开放，以解决就业、收入、经济社会发展等问题。 | C9: =Du_lieu_goc!D10 -> Việt Nam không thể đóng cửa mãi, mà phải mở cửa để giải quyết việc làm, thu nhập, phát triển kinh tế - xã hội. | D9: Việt Nam không thể tiếp tục đóng cửa mà cần mở cửa trở lại để giải quyết các vấn đề về việc làm, thu nhập, phát triển kinh tế - xã hội. | E9: Việt Nam không thể tiếp tục đóng cửa và phải mở cửa trở lại để giải quyết các vấn đề như việc làm, thu nhập và phát triển kinh tế, xã hội. | F9: Người 1 | G9: 93 | H9: 92 | I9: Người 2 | J9: 88 | K9: 91 | N9: [Thắc mắc gốc] mà/và? → [Đối chiếu bản Trung] Khác biệt "mà cần" (A) / "và phải" (B) chỉ là biến thể liên từ, không đổi nghĩa. | O9: 90 | P9: 92 | Q9: Hai người chấm thống nhất cao. A và B tương đương (90 vs 92). Ghi nhận lỗi: A: mà/và?
A10: 9 | B10: =Du_lieu_goc!C11 -> 2021年是越南实施2021-2026年新阶段性别平等战略的第一年。 | C10: =Du_lieu_goc!D11 -> Năm 2021 là năm Việt Nam bắt đầu thực hiện Chiến lược bình đẳng giới của giai đoạn mới (2021- 2026). | D10: Năm 2021 là năm đầu tiên Việt Nam triển khai chiến lược bình đẳng giới giai đoạn mới 2021-2026. | E10: Năm 2021 là năm đầu tiên Việt Nam thực hiện giai đoạn mới của Chiến lược bình đẳng giới 2021-2026. | F10: Người 1 | G10: 93 | H10: 92 | I10: Người 2 | J10: 92 | K10: 84 | N10: [Thắc mắc gốc] nghĩa khác → [Đối chiếu bản Trung] Nghi ngờ khác nghĩa: A/B dùng "năm đầu tiên triển khai", đối chiếu dùng "bắt đầu thực hiện" — tương đương. | O10: 92 | P10: 88 | Q10: Hai người chấm lệch nhẹ (8 điểm). Ghi nhận lỗi: A: nghĩa khác
A11: 10 | B11: =Du_lieu_goc!C12 -> 其他研究也显示，新冠肺炎疫情对女性产生了深远的影响，女性失业率比男性高得多，但仍要肩负在学校停课期间照顾家庭和孩子的重担。 | C11: =Du_lieu_goc!D12 -> Các nghiên cứu khác cũng cho thấy dịch Covid-19 đã tác động sâu sắc đối với phụ nữ, những người có nguy cơ mất việc làm cao hơn nhiều so với nam giới, trong khi vẫn phải đảm nhận gánh nặng trong sóc gia đình, con cái khi các trường học bị đóng cửa. | D11: Các nghiên cứu khác cũng chỉ ra rằng đại dịch COVID-19 đã tác động sâu sắc đến phụ nữ, với tỷ lệ thất nghiệp ở phụ nữ cao hơn đáng kể so với nam giới, trong khi họ vẫn phải gánh vác trách nhiệm chăm sóc gia đình và con cái trong thời gian trường học đóng cửa. | E11: Các nghiên cứu khác chỉ ra rằng đại dịch COVID-19 đã tác động sâu sắc đến phụ nữ, những người đang có tỷ lệ thất nghiệp cao hơn nhiều so với nam giới nhưng vẫn phải gánh gánh nặng chăm sóc gia đình và con cái khi trường học đóng cửa. | F11: Người 1 | G11: 90 | H11: 82 | I11: Người 2 | J11: 82 | K11: 84 | O11: 86 | P11: 83 | Q11: Hai người chấm lệch nhẹ (8 điểm). A và B tương đương (86 vs 83).
A12: 11 | B12: =Du_lieu_goc!C13 -> 特别是对越南来说，2020年以来，越南经历了4波疫情，给社会经济的所有领域造成了严重影响，成为实施性别平等和妇女进步事业乃至性别平等国家战略目标的挑战。 | C12: =Du_lieu_goc!D13 -> Riêng đối với Việt Nam, từ năm 2020 đến nay, Việt Nam đã trải qua 4 đợt bùng phát dịch, tác động nghiêm trọng tới tất cả các lĩnh vực của nền kinh tế - xã hội, gây thách thức cho việc thực hiện bình đẳng giới và vì sự tiến bộ phụ nữ cũng như việc triển khai thực hiện các mục tiêu chiến lược quốc gia về bình đẳng giới. | D12: Đặc biệt đối với Việt Nam, kể từ năm 2020, Việt Nam đã trải qua 4 đợt dịch bệnh, gây ảnh hưởng nghiêm trọng đến mọi lĩnh vực kinh tế - xã hội, trở thành thách thức đối với việc thực hiện mục tiêu bình đẳng giới và tiến bộ của phụ nữ, cũng như các mục tiêu chiến lược quốc gia về bình đẳng giới. | E12: Đặc biệt đối với Việt Nam, kể từ năm 2020, Việt Nam đã trải qua 4 đợt dịch bệnh, tác động nghiêm trọng đến mọi lĩnh vực của kinh tế xã hội và trở thành thách thức thực hiện sự nghiệp bình đẳng giới, vì sự tiến bộ của phụ nữ và thậm chí là mục tiêu chiến lược quốc gia về bình đẳng giới. | F12: Người 1 | G12: 90 | H12: 88 | I12: Người 2 | J12: 87 | K12: 82 | N12: [Thắc mắc gốc] riêng/đặc biệt? → [Đối chiếu bản Trung] Đối chiếu dùng "Riêng đối với", A/B dùng "Đặc biệt đối với". Bản Trung là 特别是 → A/B sát hơn. | O12: 88 | P12: 85 | Q12: Hai người chấm lệch nhẹ (6 điểm). A và B tương đương (88 vs 85). Ghi nhận lỗi: A: riêng/đặc biệt?
A13: 12 | B13: =Du_lieu_goc!C14 -> 越南政府总理范明政10月20日上午在15届国会2次会议开幕式上做2021年经济社会情况及2022年经济社会发展计划草案报告，概述越南各领域取得的重要结果，其中包括新冠疫情防控工作。 | C13: =Du_lieu_goc!D14 -> Báo cáo về tình hình kinh tế - xã hội năm 2021 dự kiến kế hoạch phát triển kinh tế xã hội năm 2022, tại phiên khai mạc kỳ họp thứ 2, Quốc hội khóa XV sáng 20/10, Thủ tướng Phạm Minh Chính khái quát lại những kết quả quan trọng mà Việt Nam đạt được trên các lĩnh vực, trong đó đặc biệt nhấn mạnh đến công tác phòng chống dịch COVID - 19. | D13: Sáng ngày 20 tháng 10, tại lễ khai mạc kỳ họp thứ hai, Quốc hội khóa 15, Thủ tướng Chính phủ Việt Nam Phạm Minh Chính đã trình bày báo cáo về tình hình kinh tế - xã hội năm 2021 và kế hoạch phát triển kinh tế - xã hội năm 2022. Báo cáo đã khái quát những kết quả quan trọng đạt được trên các lĩnh vực của Việt Nam, trong đó có công tác phòng, chống dịch bệnh COVID-19. | E13: Sáng 20/10, Thủ tướng Phạm Minh Chính đã báo cáo về tình hình kinh tế, xã hội năm 2021 và dự thảo kế hoạch phát triển kinh tế, xã hội năm 2022 tại lễ khai mạc kỳ họp thứ hai, Quốc hội lần thứ 15, nêu những kết quả quan trọng đạt được trên nhiều lĩnh vực ở Việt Nam, trong đó có công tác phòng, chống dịch bệnh vương miện mới. | F13: Người 1 | G13: 90 | H13: 45 | I13: Người 2 | J13: 80 | K13: 52 | M13: “Quốc hội khóa XV” bị đổi thành “Quốc hội lần thứ 15” và COVID-19 thành “dịch bệnh vương miện mới”, làm sai thuật ngữ quan trọng. | N13: [Thắc mắc gốc] trong đó đặc biệt? → [Đối chiếu bản Trung] Đối chiếu thêm "đặc biệt nhấn mạnh", bản Trung chỉ có 其中包括 (trong đó bao gồm) → đối chiếu tự thêm sắc thái. | O13: 85 | P13: 48 | Q13: Hai người chấm lệch nhẹ (10 điểm). A vượt B rõ rệt (85 vs 48). Ghi nhận lỗi: A: trong đó đặc biệt? | B: “Quốc hội khóa XV” bị đổi thành “Quốc hội lần thứ 15” và COVID-19 thành “dịch bệnh vương miện mới”, làm sai thuật ngữ quan trọng. Điểm thấp — nên kiểm tra thủ công trước khi đưa vào tính tương quan.
A14: 13 | B14: =Du_lieu_goc!C15 -> 集中复苏经济，维持增长动力 | C14: =Du_lieu_goc!D15 -> Tập trung phục hồi kinh tế, duy trì các động lực tăng trưởng | D14: Tập trung phục hồi kinh tế, duy trì động lực tăng trưởng | E14: Tập trung phục hồi nền kinh tế và duy trì đà tăng trưởng | F14: Người 1 | G14: 93 | H14: 90 | I14: Người 2 | J14: 90 | K14: 82 | O14: 92 | P14: 86 | Q14: Hai người chấm lệch nhẹ (8 điểm).
A15: 14 | B15: =Du_lieu_goc!C16 -> 防疫工作是政府指导、调控工作的优先 | C15: =Du_lieu_goc!D16 -> Công tác phòng, chống dịch COVID-19 là ưu tiên hàng đầu trong chỉ đạo, điều hành | D15: Công tác phòng chống dịch bệnh là ưu tiên hàng đầu trong công tác chỉ đạo và điều tiết của chính phủ. | E15: Công tác phòng chống dịch bệnh là ưu tiên trong hướng dẫn và quy định của chính phủ | F15: Người 1 | G15: 90 | H15: 78 | I15: Người 2 | J15: 82 | K15: 60 | M15: “Chỉ đạo, điều hành” bị đổi thành “hướng dẫn và quy định”, làm lệch vai trò của Chính phủ. | N15: [Thắc mắc gốc] Mất từ COVID → [Đối chiếu bản Trung] Đối chiếu thêm "COVID-19", bản Trung chỉ ghi 防疫工作 (công tác phòng dịch) → đối chiếu tự thêm. | O15: 86 | P15: 69 | Q15: LỆCH LỚN 18 điểm giữa chấm chính và chấm chéo — cần rà lại. A vượt B rõ rệt (86 vs 69). Ghi nhận lỗi: A: Mất từ COVID | B: “Chỉ đạo, điều hành” bị đổi thành “hướng dẫn và quy định”, làm lệch vai trò của Chính phủ.
A16: 15 | B16: =Du_lieu_goc!C17 -> 集中复苏经济，维持增长动力,不让增长动力减弱 | C16: =Du_lieu_goc!D17 -> Tập trung khôi phục kinh tế , duy trì động lực tăng trưởng , không để suy giảm động lực tăng trưởng | D16: Tập trung phục hồi kinh tế, duy trì động lực tăng trưởng, không để động lực tăng trưởng suy yếu. | E16: Tập trung phục hồi nền kinh tế, duy trì đà tăng trưởng, ngăn chặn đà tăng trưởng suy yếu | F16: Người 1 | G16: 90 | H16: 90 | I16: Người 2 | J16: 91 | K16: 84 | N16: [Thắc mắc gốc] B nên thấp hơn A → [Đối chiếu bản Trung] Đề xuất B thấp hơn A: B dùng "ngăn chặn đà tăng trưởng suy yếu" — diễn đạt kém tự nhiên hơn A. | O16: 90 | P16: 87 | Q16: Hai người chấm lệch nhẹ (6 điểm). A và B tương đương (90 vs 87). Ghi nhận lỗi: A: B nên thấp hơn A
A17: 16 | B17: =Du_lieu_goc!C18 -> 范明政强调，今年最后几个月将集中防疫，制定安全、灵活路线图，有效控制疫情，克服疫情后果，恢复、发展经济社会。 | C17: =Du_lieu_goc!D18 -> Thủ tướng Phạm Minh Chính khẳng định trong những tháng cuối năm, sẽ tập trung nỗ lực cao nhất cho phòng, chống dịch COVID-19, có lộ trình thích ứng an toàn, linh hoạt, phấn đấu kiểm soát hiệu quả dịch bệnh trên phạm vi toàn quốc để tập trung khắc phục hậu quả của dịch bệnh và khôi phục, phát triển kinh tế xã hội. | D17: Phạm Minh Chính nhấn mạnh, những tháng cuối năm sẽ tập trung phòng chống dịch bệnh, xây dựng lộ trình an toàn, linh hoạt, kiểm soát hiệu quả dịch bệnh, khắc phục hậu quả dịch bệnh, phục hồi và phát triển kinh tế xã hội. | E17: Fan Mingzheng nhấn mạnh, trong những tháng cuối năm nay, chúng ta sẽ tập trung vào công tác phòng chống dịch bệnh, xây dựng lộ trình an toàn và linh hoạt, kiểm soát dịch bệnh hiệu quả, khắc phục hậu quả của dịch bệnh, khôi phục và phát triển kinh tế, xã hội. | F17: Người 1 | G17: 90 | H17: 40 | I17: =I16 -> Người 2 | J17: 78 | K17: 42 | L17: Bỏ nhiều ý trong tham chiếu như “nỗ lực cao nhất”, “phấn đấu” và “trên phạm vi toàn quốc”, nên mức độ và phạm vi hành động bị giảm. | M17: Sai tên Phạm Minh Chính thành “Fan Mingzheng”; đồng thời cũng bỏ nhiều ý về mức độ và phạm vi hành động. | N17: [Thắc mắc gốc] "Tập trung cao nhất" cả 2 chưa diễn giải được → [Đối chiếu bản Trung] Cả A và B đều chưa diễn đạt được "tập trung cao nhất"; nhưng bản Trung chỉ có 集中 → không phải lỗi của bản dịch. | O17: 84 | P17: 41 | Q17: Hai người chấm lệch nhẹ (12 điểm). A vượt B rõ rệt (84 vs 41). Ghi nhận lỗi: A: "Tập trung cao nhất" cả 2 chưa diễn giải được | B: Sai tên Phạm Minh Chính thành “Fan Mingzheng”; đồng thời cũng bỏ nhiều ý về mức độ và phạm vi hành động. Điểm thấp — nên kiểm tra thủ công trước khi đưa vào tính tương quan.
A18: 17 | B18: =Du_lieu_goc!C19 -> 政府也灵活调整财政、货币及其他政策以保障宏观经济稳定，促进生产经营；开展切实、有效帮扶政策、机制。 | C18: =Du_lieu_goc!D19 -> Chính phủ cũng sẽ điều chỉnh linh hoạt chính sách tài khóa, tiền tệ và các chính sách khác để giữ vững ổn định vĩ mô, bảo đảm các cân đối lớn, thúc đẩy sản xuất kinh doanh, tập trung ưu tiên triển khai các cơ chế, chính sách hỗ trợ thiết thực, hiệu quả . | D18: Chính phủ cũng linh hoạt điều chỉnh các chính sách tài khóa, tiền tệ và các chính sách khác để đảm bảo ổn định kinh tế vĩ mô, thúc đẩy sản xuất kinh doanh; triển khai các chính sách, cơ chế hỗ trợ thiết thực, hiệu quả. | E18: Chính phủ cũng đã điều chỉnh linh hoạt các chính sách tài khóa, tiền tệ và các chính sách khác nhằm bảo đảm ổn định kinh tế vĩ mô và thúc đẩy sản xuất kinh doanh; triển khai các chính sách, cơ chế hỗ trợ thiết thực, hiệu quả. | F18: Người 1 | G18: 90 | H18: 80 | I18: =I17 -> Người 2 | J18: 76 | K18: 50 | L18: Tham chiếu dùng “sẽ điều chỉnh”, còn bản dịch bỏ dấu hiệu tương lai, làm yếu thông tin thời của chính sách. | M18: [Thắc mắc gốc] câu b sử dụng từ đã làm sai đi ý của câu hiện tại khá nhiều. → [Đối chiếu bản Trung] B dùng thì quá khứ "đã điều chỉnh" trong khi bản Trung là hành động tiếp diễn/tương lai → lệch thì. || Tham chiếu dùng “sẽ điều chỉnh”, nhưng bản dịch chuyển thành “đã điều chỉnh”, làm đổi hành động tương lai thành đã hoàn tất. | O18: 83 | P18: 65 | Q18: LỆCH LỚN 30 điểm giữa chấm chính và chấm chéo — cần rà lại. A vượt B rõ rệt (83 vs 65). Ghi nhận lỗi: A: câu b sử dụng từ đã làm sai đi ý của câu hiện tại khá nhiều. | B: Tham chiếu dùng “sẽ điều chỉnh”, nhưng bản dịch chuyển thành “đã điều chỉnh”, làm đổi hành động tương lai thành đã hoàn tất.
A19: 18 | B19: =Du_lieu_goc!C20 -> 为实现16个指标，范明政提出12个主要任务和措施，其中包括灵活、有效实施防疫措施并复苏、发展经济社会；优先制定、完善体制，改革行政手续，改善营商投资环境。 | C19: =Du_lieu_goc!D20 -> Để thực hiện 16 chỉ tiêu này là 12 nhiệm vụ, giải pháp chủ yếu, trong đó đầu tiên là tập trung thực hiện linh hoạt, hiệu quả mục tiêu vừa phòng, chống dịch COVID-19, vừa phục hồi, phát triển KTXH; tiếp đó là ưu tiên công tác xây dựng, hoàn thiện thể chế, tập trung tháo gỡ khó khăn, cải cách thủ tục hành chính, cải thiện môi trường đầu tư kinh doanh. | D19: Để thực hiện 16 chỉ tiêu, Phạm Minh Chính đã đề xuất 12 nhiệm vụ và giải pháp trọng tâm, bao gồm việc triển khai linh hoạt, hiệu quả các biện pháp phòng chống dịch bệnh, đồng thời phục hồi và phát triển kinh tế - xã hội; ưu tiên xây dựng, hoàn thiện thể chế, cải cách thủ tục hành chính, cải thiện môi trường kinh doanh và đầu tư. | E19: Để đạt được 16 chỉ số, Fan Mingzheng đề xuất 12 nhiệm vụ, biện pháp chính, bao gồm thực hiện linh hoạt, hiệu quả các biện pháp phòng chống dịch bệnh và phục hồi, phát triển kinh tế, xã hội; ưu tiên xây dựng và hoàn thiện hệ thống, cải cách thủ tục hành chính, cải thiện môi trường đầu tư, kinh doanh. | F19: Người 1 | G19: 90 | H19: 42 | I19: =I18 -> Người 2 | J19: 78 | K19: 38 | L19: Bỏ thứ tự “đầu tiên/tiếp đó” và ý “tập trung tháo gỡ khó khăn”, làm thiếu một phần đáng kể của nhóm nhiệm vụ. | M19: [Thắc mắc gốc] Sai tên, chỉ tiêu -> chỉ số khá sai nghĩa tuy nhiên không phải là đánh giá chính, → [Đối chiếu bản Trung] B sai tên riêng ("Fan Mingzheng" thay vì Phạm Minh Chính) và dịch 指标 thành "chỉ số" thay vì "chỉ tiêu". || Sai tên Phạm Minh Chính; “16 chỉ tiêu” thành “16 chỉ số”, “hoàn thiện thể chế” thành “hoàn thiện hệ thống” và còn bỏ ý tháo gỡ khó khăn. | O19: 84 | P19: 40 | Q19: Hai người chấm lệch nhẹ (12 điểm). A vượt B rõ rệt (84 vs 40). Ghi nhận lỗi: A: Sai tên, chỉ tiêu -> chỉ số khá sai nghĩa tuy nhiên không phải là đánh giá chính, | B: Sai tên Phạm Minh Chính; “16 chỉ tiêu” thành “16 chỉ số”, “hoàn thiện thể chế” thành “hoàn thiện hệ thống” và còn bỏ ý tháo gỡ khó khăn. Điểm thấp — nên kiểm tra thủ công trước khi đưa vào tính tương quan.
A20: 19 | B20: =Du_lieu_goc!C21 -> 配套、高效开展对外活动，主动、积极融入国际，巩固越南在国际舞台上的地位和威望。 | C20: =Du_lieu_goc!D21 -> Triển khai đồng bộ, hiệu quả hoạt động đối ngoại, chủ động, tích cực hội nhập quốc tế, góp phần củng cố vị thế, uy tín của Việt Nam trên trường quốc tế. | D20: Tổ chức các hoạt động đối ngoại đồng bộ, hiệu quả, chủ động, tích cực hội nhập quốc tế, củng cố vị thế và uy tín của Việt Nam trên trường quốc tế. | E20: Chúng ta sẽ thực hiện các hoạt động đối ngoại hỗ trợ và hiệu quả, chủ động, tích cực hội nhập quốc tế, củng cố vị thế và uy tín của Việt Nam trên trường quốc tế. | F20: Người 1 | G20: 87 | H20: 72 | I20: =I19 -> Người 2 | J20: 90 | K20: 58 | M20: Tự thêm “chúng ta sẽ”, làm thay đổi chủ thể diễn ngôn và thêm nghĩa tương lai không có trong tham chiếu. | O20: 88 | P20: 65 | Q20: Hai người chấm lệch nhẹ (14 điểm). A vượt B rõ rệt (88 vs 65). Ghi nhận lỗi: B: Tự thêm “chúng ta sẽ”, làm thay đổi chủ thể diễn ngôn và thêm nghĩa tương lai không có trong tham chiếu.
A21: 20 | B21: =Du_lieu_goc!C22 -> 有效开展战略伙伴关系、全面伙伴关系框架及自贸协定。 | C21: =Du_lieu_goc!D22 -> Tăng cường các hoạt động ngoại giao cấp cao, khai thác hiệu quả các khuôn khổ quan hệ đối tác chiến lược, đối tác toàn diện, các hiệp định thương mại tự do (FTA). | D21: Triển khai hiệu quả quan hệ đối tác chiến lược, khuôn khổ quan hệ đối tác toàn diện và hiệp định thương mại tự do. | E21: Triển khai hiệu quả các quan hệ đối tác chiến lược, khuôn khổ đối tác toàn diện và các hiệp định thương mại tự do. | F21: Người 1 | G21: 90 | H21: 90 | I21: =I20 -> Người 2 | J21: 70 | K21: 72 | L21: [Thắc mắc gốc] A, không có "các" điểm < B → [Đối chiếu bản Trung] A thiếu mạo từ "các" trước "quan hệ đối tác chiến lược" → kém trôi chảy hơn B một chút. || Bỏ toàn bộ ý “tăng cường các hoạt động ngoại giao cấp cao”, là một nội dung độc lập trong tham chiếu. | M21: Bỏ toàn bộ ý “tăng cường các hoạt động ngoại giao cấp cao”, là một nội dung độc lập trong tham chiếu. | O21: 80 | P21: 81 | Q21: LỆCH LỚN 20 điểm giữa chấm chính và chấm chéo — cần rà lại. A và B tương đương (80 vs 81). Ghi nhận lỗi: A: A, không có "các" điểm < B | B: Bỏ toàn bộ ý “tăng cường các hoạt động ngoại giao cấp cao”, là một nội dung độc lập trong tham chiếu.
A22: 21 | B22: =Du_lieu_goc!C23 -> 进一步做好对外新闻工作、文化外交、海外越南人工作等”。 | C22: =Du_lieu_goc!D23 -> Làm tốt hơn nữa công tác thông tin đối ngoại, ngoại giao văn hóa, công tác người Việt Nam ở nước ngoài và bảo hộ công dân". | D22: Tiếp tục làm tốt công tác báo chí đối ngoại, ngoại giao văn hóa, công tác đối với người Việt Nam ở nước ngoài, v.v. | E22: Chúng tôi sẽ nâng cao hơn nữa công tác thông tấn đối ngoại, ngoại giao văn hóa, công tác người Việt Nam ở nước ngoài, v.v.” | F22: Người 1 | G22: 85 | H22: 75 | I22: =I21 -> Người 2 | J22: 68 | K22: 50 | L22: Bỏ nội dung “bảo hộ công dân” trong tham chiếu. | M22: Bỏ “bảo hộ công dân” và tự thêm “chúng tôi sẽ”, làm thay đổi cả nội dung lẫn chủ thể/tình thái. | N22: [Thắc mắc gốc] Đối chiếu không có "v.v" → [Đối chiếu bản Trung] Đối chiếu không có "v.v." nhưng bản Trung có 等 → A/B thêm "v.v." là đúng với bản Trung. | O22: 76 | P22: 62 | Q22: LỆCH LỚN 25 điểm giữa chấm chính và chấm chéo — cần rà lại. Ghi nhận lỗi: A: Đối chiếu không có "v.v" | B: Bỏ “bảo hộ công dân” và tự thêm “chúng tôi sẽ”, làm thay đổi cả nội dung lẫn chủ thể/tình thái.
A23: 22 | B23: =Du_lieu_goc!C24 -> 范明政表示，相信以全民族大团结及人民对党的领导的信心，越南必将击退疫情，复苏和发展经济社会，推动国家在革新、融入与发展道路上稳步前进。 | C23: =Du_lieu_goc!D24 -> Người đứng đầu Chính phủ tin tưởng với sức mạnh đại đoàn kết toàn dân tộc và niềm tin của Nhân dân vào sự lãnh đạo của Đảng, nhất định Việt Nam sẽ sớm đẩy lùi dịch bệnh để phục hồi và phát triển KTXH, đưa đất nước vững bước tiến lên trên con đường đổi mới, hội nhập và phát triển. | D23: Phạm Minh Chính bày tỏ tin tưởng rằng, với sự đoàn kết toàn dân tộc và niềm tin của nhân dân vào sự lãnh đạo của Đảng, Việt Nam nhất định sẽ đẩy lùi dịch bệnh, phục hồi và phát triển kinh tế - xã hội, đưa đất nước vững bước tiến trên con đường đổi mới, hội nhập và phát triển. | E23: Phạm Minh Chính bày tỏ tin tưởng với sự đoàn kết to lớn của toàn dân tộc và sự tin tưởng của nhân dân vào sự lãnh đạo của Đảng, Việt Nam sẽ đẩy lùi dịch bệnh, phục hồi và phát triển kinh tế, xã hội, thúc đẩy đất nước vững bước trên con đường đổi mới, hội nhập và phát triển. | F23: Người 1 | G23: 90 | H23: 88 | I23: =I22 -> Người 2 | J23: 88 | K23: 86 | N23: [Thắc mắc gốc] "PMC" ở đâu ra vậy → [Đối chiếu bản Trung] Đối chiếu dùng "Người đứng đầu Chính phủ", A/B dùng đích danh "Phạm Minh Chính" — bản Trung ghi 范明政 nên A/B sát hơn. | O23: 89 | P23: 87 | Q23: Hai người chấm thống nhất cao. A và B tương đương (89 vs 87). Ghi nhận lỗi: A: "PMC" ở đâu ra vậy
A24: 23 | B24: =Du_lieu_goc!C25 -> 叙利亚政府和反对派日前正式同意在联合国的参与下开始修宪进程。 | C24: =Du_lieu_goc!D25 -> Chính phủ Syria và phe đối lập vừa chính thức nhất trí khởi động tiến trình soạn thảo nội dung sửa đổi hiếp pháp, dưới sự tham gia của Liên Hợp Quốc. | D24: Chính phủ Syria và phe đối lập mới đây đã chính thức đồng ý khởi động tiến trình sửa đổi hiến pháp dưới sự tham gia của Liên Hợp Quốc. | E24: Chính phủ Syria và các đảng đối lập mới đây đã chính thức đồng ý bắt đầu quá trình sửa đổi hiến pháp với sự tham gia của Liên hợp quốc. | F24: Người 1 | G24: 92 | H24: 88 | I24: =I23 -> Người 2 | J24: 90 | K24: 84 | O24: 91 | P24: 86 | Q24: Hai người chấm thống nhất cao.
A25: 24 | B25: =Du_lieu_goc!C26 -> 叙利亚宪法委员会在日内瓦举行的本轮磋商计划持续一周，希望达成全面、长期的法律基础，解决叙利亚各党派的分歧，为更广泛的政治进程敞开大门。 | C25: =Du_lieu_goc!D26 -> Vòng đàm phán Ủy ban Hiến pháp Syria (SCC) tiến hành tại Geneva lần này dự kiến kéo dài trong 1 tuần, với mong muốn đạt được một cơ sở pháp lý toàn diện, lâu dài, khắc phục sự khác biệt giữa các đảng phái tại Syria và mở ra cánh cửa cho một tiến trình chính trị rộng lớn hơn. | D25: Vòng đàm phán lần này của Ủy ban Hiến pháp Syria tại Geneva dự kiến kéo dài một tuần, với hy vọng đạt được nền tảng pháp lý toàn diện và lâu dài, giải quyết những bất đồng giữa các bên tại Syria, mở đường cho một tiến trình chính trị rộng lớn hơn. | E25: Vòng tham vấn hiện tại do Ủy ban Hiến pháp Syria tổ chức tại Geneva dự kiến ​​sẽ kéo dài trong một tuần, với hy vọng đạt được cơ sở pháp lý toàn diện và lâu dài, giải quyết những khác biệt giữa các đảng phái ở Syria và mở ra cánh cửa cho một tiến trình chính trị rộng lớn hơn. | F25: Người 1 | G25: 90 | H25: 88 | I25: =I24 -> Người 2 | J25: 88 | K25: 94 | L25: [Thắc mắc gốc] A < B, do A không có "đảng phái" → [Đối chiếu bản Trung] A thiếu "đảng phái" khi dịch 各党派 → B đầy đủ hơn ở chi tiết này. | O25: 89 | P25: 91 | Q25: Hai người chấm lệch nhẹ (6 điểm). A và B tương đương (89 vs 91). Ghi nhận lỗi: A: A < B, do A không có "đảng phái"
A26: 25 | B26: =Du_lieu_goc!C27 -> 过去2年，该委员会开了5次会，但由于反对派和叙利亚政府之间存在分歧，均未取得进展，尽管该中东国家数百万人须等待新宪法生效后才能举行全国大选。 | C26: =Du_lieu_goc!D27 -> Trong 2 năm qua, ủy ban này đã nhóm họp 5 lần, nhưng kết quả thu lại không đáng kể do các bất đồng giữa phe đối lập và Chính phủ Syria, bất chấp việc hàng triệu người dân quốc gia Trung Đông vẫn đang mòn mỏi chờ đợi một cuộc bầu cử quy mô toàn quốc, vốn chỉ được tiến hành sau khi có hiến pháp mới. | D26: Trong 2 năm qua, ủy ban này đã họp 5 lần, nhưng do những bất đồng giữa phe đối lập và chính phủ Syria, không có tiến triển nào đạt được, mặc dù hàng triệu người dân nước này đang chờ đợi cuộc tổng tuyển cử diễn ra sau khi hiến pháp mới có hiệu lực. | E26: Ủy ban đã họp năm lần trong hai năm qua nhưng không đạt được tiến bộ nào do sự khác biệt giữa phe đối lập và chính phủ Syria, ngay cả khi hàng triệu người dân ở quốc gia Trung Đông này phải chờ hiến pháp mới có hiệu lực trước khi các cuộc bầu cử quốc gia được tổ chức. | F26: Người 1 | G26: 90 | H26: 87 | I26: =I25 -> Người 2 | J26: 84 | K26: 83 | L26: “Kết quả không đáng kể” bị đổi thành “không có tiến triển nào”, làm tăng mức độ phủ định so với tham chiếu. | M26: [Thắc mắc gốc] Đọc thấy B sai nghĩa? → [Đối chiếu bản Trung] B đảo cấu trúc câu và dùng "ngay cả khi", làm quan hệ nhân-quả mờ hơn bản Trung. || “Kết quả không đáng kể” bị đổi thành “không đạt được tiến bộ nào”, làm tăng mức độ phủ định so với tham chiếu. | O26: 87 | P26: 85 | Q26: Hai người chấm lệch nhẹ (6 điểm). A và B tương đương (87 vs 85). Ghi nhận lỗi: A: Đọc thấy B sai nghĩa? | B: “Kết quả không đáng kể” bị đổi thành “không đạt được tiến bộ nào”, làm tăng mức độ phủ định so với tham chiếu.
A27: 26 | B27: =Du_lieu_goc!C28 -> 因此，观察人士希望本轮对话有助于叙利亚制定双方都能接受的新宪法。 | C27: =Du_lieu_goc!D28 -> Vì vậy, giới quan sát hy vọng vòng đối thoại lần này giúp Syria có một bản hiến pháp mới mà các bên cùng có thể chấp nhận. | D27: Vì vậy, các nhà quan sát hy vọng vòng đối thoại lần này sẽ giúp Syria soạn thảo một hiến pháp mới mà cả hai bên đều có thể chấp nhận. | E27: Vì vậy, giới quan sát hy vọng vòng đối thoại này sẽ giúp Syria xây dựng một hiến pháp mới được cả hai bên chấp nhận. | F27: Người 1 | G27: 90 | H27: 90 | I27: =I26 -> Người 2 | J27: 93 | K27: 93 | O27: 92 | P27: 92 | Q27: Hai người chấm thống nhất cao. A và B tương đương (92 vs 92).
A28: 27 | B28: =Du_lieu_goc!C29 -> 叙利亚10多年的冲突中，西方国家、阿拉伯国家与支持叙利亚政府的俄罗斯、中国和伊朗之间存在深刻分歧。 | C28: =Du_lieu_goc!D29 -> Hơn 10 năm xung đột ở Syria, với sự bất đồng sâu sắc giữa một bên là các nước phương Tây cùng khối Arab và bên kia là Nga, Trung Quốc và Iran. | D28: Trong cuộc xung đột kéo dài hơn một thập kỷ tại Syria, các nước phương Tây, các quốc gia Ả Rập và Nga, Trung Quốc, Iran ủng hộ chính phủ Syria đã tồn tại những bất đồng sâu sắc. | E28: Trong cuộc xung đột kéo dài hơn 10 năm ở Syria, đã có sự khác biệt sâu sắc giữa các nước phương Tây, các nước Ả Rập và Nga, Trung Quốc, Iran ủng hộ chính phủ Syria. | F28: Người 1 | G28: 88 | H28: 87 | I28: =I27 -> Người 2 | J28: 72 | K28: 72 | L28: Cấu trúc câu làm mờ quan hệ đối lập giữa một bên là phương Tây/Ả Rập và bên kia là Nga–Trung–Iran. | M28: Cấu trúc câu làm mờ quan hệ đối lập giữa hai nhóm quốc gia được nêu trong tham chiếu. | N28: [Thắc mắc gốc] Có "ủng hộ" ở bản gốc thật à → [Đối chiếu bản Trung] Bản Trung có 支持叙利亚政府的 (ủng hộ chính phủ Syria) — A/B dịch đúng, đối chiếu lược bỏ ý này. | O28: 80 | P28: 80 | Q28: LỆCH LỚN 16 điểm giữa chấm chính và chấm chéo — cần rà lại. A và B tương đương (80 vs 80). Ghi nhận lỗi: A: Có "ủng hộ" ở bản gốc thật à | B: Cấu trúc câu làm mờ quan hệ đối lập giữa hai nhóm quốc gia được nêu trong tham chiếu.
A29: 28 | B29: =Du_lieu_goc!C30 -> 目前，叙利亚政府已经夺回大部分领土的控制权，但基础设施遭到严重破坏，需要数十年或数百年的时间才能恢复。 | C29: =Du_lieu_goc!D30 -> Đến nay, Chính phủ Syria đã giành lại gần hết quyền kiểm soát lãnh thổ nhưng hạ tầng cơ sở đã bị tàn phá nặng nề phải mất hàng chục hoặc hàng trăm năm sau mới phục hồi. | D29: Hiện tại, chính phủ Syria đã giành lại quyền kiểm soát phần lớn lãnh thổ, nhưng cơ sở hạ tầng bị tàn phá nặng nề, cần nhiều thập kỷ hoặc thậm chí hàng thế kỷ để phục hồi. | E29: Chính phủ Syria đã giành lại quyền kiểm soát phần lớn lãnh thổ, nhưng cơ sở hạ tầng đã bị hư hại nghiêm trọng và sẽ phải mất hàng thập kỷ hoặc thế kỷ để phục hồi. | F29: Người 1 | G29: 90 | H29: 90 | I29: =I28 -> Người 2 | J29: 82 | K29: 80 | L29: “Gần hết quyền kiểm soát lãnh thổ” bị giảm thành “phần lớn lãnh thổ”, làm thay đổi phạm vi định lượng. | M29: “Gần hết quyền kiểm soát lãnh thổ” bị giảm thành “phần lớn lãnh thổ”, làm thay đổi phạm vi định lượng. | O29: 86 | P29: 85 | Q29: Hai người chấm lệch nhẹ (10 điểm). A và B tương đương (86 vs 85). Ghi nhận lỗi: A: “Gần hết quyền kiểm soát lãnh thổ” bị giảm thành “phần lớn lãnh thổ”, làm thay đổi phạm vi định lượng. | B: “Gần hết quyền kiểm soát lãnh thổ” bị giảm thành “phần lớn lãnh thổ”, làm thay đổi phạm vi định lượng.
A30: 29 | B30: =Du_lieu_goc!C31 -> 令人担忧的是，儿童是叙利亚长期冲突中最大的受害者。 | C30: =Du_lieu_goc!D31 -> Đáng quan ngại, là trẻ em chính là nạn nhân chịu ảnh hưởng lớn nhất trong cuộc xung đột kéo dài ở Syria. | D30: Điều đáng lo ngại là trẻ em là những nạn nhân lớn nhất trong cuộc xung đột kéo dài ở Syria. | E30: Điều đáng lo ngại là trẻ em là nạn nhân lớn nhất trong cuộc xung đột kéo dài ở Syria. | F30: Người 1 | G30: 95 | H30: 95 | I30: =I29 -> Người 2 | J30: 94 | K30: 94 | O30: 94 | P30: 94 | Q30: Hai người chấm thống nhất cao. A và B tương đương (94 vs 94).
A31: 30 | B31: =Du_lieu_goc!C32 -> 据联合国儿童基金会的报告，过去10年，超过100万儿童在叙利亚境外的难民营出生，350万儿童失学，90%的叙利亚儿童急需救济。 | C31: =Du_lieu_goc!D32 -> Theo báo cáo của Quỹ Nhi đồng Liên Hợp Quốc, trong vòng 10 năm qua, hơn 1 triệu trẻ em được sinh ra trong các trại tị nạn ngoài Syria, 3,5 triệu trẻ em thất học, 90% trẻ em Syria đang rất cần được hỗ trợ cả về vật chất và tâm lý. | D31: Theo báo cáo của Quỹ Nhi đồng Liên Hợp Quốc, trong 10 năm qua, hơn 1 triệu trẻ em đã chào đời tại các trại tị nạn bên ngoài Syria, 3,5 triệu trẻ em không được đến trường và 90% trẻ em Syria đang rất cần viện trợ nhân đạo. | E31: Theo báo cáo của Quỹ Nhi đồng Liên hợp quốc, hơn 1 triệu trẻ em đã được sinh ra trong các trại tị nạn bên ngoài Syria trong 10 năm qua, 3,5 triệu trẻ em không được đến trường và 90% trẻ em Syria đang cần được cứu trợ khẩn cấp. | F31: Người 1 | G31: 90 | H31: 90 | I31: =I30 -> Người 2 | J31: 76 | K31: 74 | L31: Tham chiếu nêu hỗ trợ “cả về vật chất và tâm lý”, nhưng bản dịch khái quát thành “viện trợ nhân đạo”, làm mất hai nội dung cụ thể. | M31: Tham chiếu nêu hỗ trợ “cả về vật chất và tâm lý”, nhưng bản dịch chỉ nói “cứu trợ khẩn cấp”, làm mất hai nội dung cụ thể. | N31: [Thắc mắc gốc] Ý cuối chưa rõ có cùng ý nghĩa không → [Đối chiếu bản Trung] Ý cuối: bản Trung 急需救济 (cần cứu trợ khẩn cấp); đối chiếu mở rộng thành "hỗ trợ cả vật chất và tâm lý" → đối chiếu tự thêm. | O31: 83 | P31: 82 | Q31: LỆCH LỚN 16 điểm giữa chấm chính và chấm chéo — cần rà lại. A và B tương đương (83 vs 82). Ghi nhận lỗi: A: Ý cuối chưa rõ có cùng ý nghĩa không | B: Tham chiếu nêu hỗ trợ “cả về vật chất và tâm lý”, nhưng bản dịch chỉ nói “cứu trợ khẩn cấp”, làm mất hai nội dung cụ thể.
A32: 31 | B32: =Du_lieu_goc!C33 -> 而叙利亚冲突每天都在继续。 | C32: =Du_lieu_goc!D33 -> Trong khi đó, xung đột ở Syria vẫn tiếp tục diễn ra hàng ngày. | D32: Và cuộc xung đột ở Syria vẫn tiếp diễn hàng ngày. | E32: Và cuộc xung đột ở Syria vẫn tiếp diễn mỗi ngày. | F32: Người 1 | G32: 95 | H32: 95 | I32: =I31 -> Người 2 | J32: 93 | K32: 93 | N32: [Thắc mắc gốc] "Trong khi đó" và "và"? → [Đối chiếu bản Trung] Khác biệt "Trong khi đó" / "Và" chỉ là liên từ chuyển ý, không ảnh hưởng nghĩa. | O32: 94 | P32: 94 | Q32: Hai người chấm thống nhất cao. A và B tương đương (94 vs 94). Ghi nhận lỗi: A: "Trong khi đó" và "và"?
A33: 32 | B33: =Du_lieu_goc!C34 -> 这令人担忧，尽管得到了许多国际组织和有关国家的支持，但叙利亚恢复和平仍然是一个难题。 | C33: =Du_lieu_goc!D34 -> Điều này làm dấy lên quan ngại mặc dù được nhiều tổ chức quốc tế và các quốc gia liên quan quan tâm hỗ trợ, tuy nhiên, việc lập lại hòa bình cho Syria vẫn còn là bài toán khó. | D33: Điều này thật đáng lo ngại, mặc dù đã nhận được sự ủng hộ của nhiều tổ chức quốc tế và các quốc gia liên quan, nhưng việc khôi phục hòa bình cho Syria vẫn là một thách thức lớn. | E33: Điều này thật đáng lo ngại. Bất chấp sự hỗ trợ của nhiều tổ chức quốc tế và các nước liên quan, việc khôi phục hòa bình ở Syria vẫn là một bài toán khó. | F33: Người 1 | G33: 90 | H33: 88 | I33: =I32 -> Người 2 | J33: 88 | K33: 92 | O33: 89 | P33: 90 | Q33: Hai người chấm thống nhất cao. A và B tương đương (89 vs 90).
A34: 33 | B34: =Du_lieu_goc!C35 -> 越南政府颁布关于“安全、灵活适应并有效控制新冠肺炎疫情”的第128号决议后，各部门、各地方迅速从“封闭”模式转为“新常态”模式。 | C34: =Du_lieu_goc!D35 -> Sau khi chính phủ Việt Nam ban bố nghị quyết 128 “thích ứng an toàn, linh hoạt, kiểm soát hiệu quả dịch Covid-19”, mhiều bộ, ngành, địa phương tại Việt Nam nhanh chóng chuyển từ trạng thái “đóng cửa” sang trạng thái thích ứng bình thường mới. | D34: Sau khi Chính phủ Việt Nam ban hành Nghị quyết số 128 về "An toàn, linh hoạt thích ứng và kiểm soát hiệu quả dịch COVID-19", các bộ, ngành, địa phương đã nhanh chóng chuyển đổi từ trạng thái "đóng băng" sang trạng thái "bình thường mới". | E34: Sau khi Chính phủ ban hành Nghị quyết số 128 về “Thích ứng an toàn, linh hoạt và kiểm soát hiệu quả dịch bệnh Covid-19”, nhiều sở, ngành, địa phương đã nhanh chóng chuyển từ chế độ “đóng cửa” sang chế độ “bình thường mới”. | F34: Người 1 | G34: 80 | H34: 90 | I34: =I33 -> Người 2 | J34: 82 | K34: 75 | M34: “Bộ, ngành” bị đổi thành “sở, ngành”, làm sai cấp đơn vị được nhắc đến. | O34: 81 | P34: 82 | Q34: LỆCH LỚN 15 điểm giữa chấm chính và chấm chéo — cần rà lại. A và B tương đương (81 vs 82). Ghi nhận lỗi: B: “Bộ, ngành” bị đổi thành “sở, ngành”, làm sai cấp đơn vị được nhắc đến.
A35: 34 | B35: =Du_lieu_goc!C36 -> 九龙江平原地区集中防控疫情3个月后，多个省市目前已经基本控制了疫情。 | C35: =Du_lieu_goc!D36 -> Tại đồng bằng sông Cửu Long, sau 3 tháng tập trung phòng, chống dịch Covid-19, đến nay nhiều tỉnh đã cơ bản kiểm soát được dịch. | D35: Sau 3 tháng tập trung phòng chống dịch tại vùng đồng bằng sông Cửu Long, nhiều tỉnh thành hiện đã cơ bản kiểm soát được dịch bệnh. | E35: Ba tháng sau khi phòng chống dịch tập trung ở đồng bằng Cửu Long Giang, nhiều tỉnh, thành phố hiện đã cơ bản kiểm soát được dịch bệnh. | F35: Người 1 | G35: 90 | H35: 78 | I35: =I34 -> Người 2 | J35: 94 | K35: 78 | O35: 92 | P35: 78 | Q35: Hai người chấm thống nhất cao.
A36: 35 | B36: =Du_lieu_goc!C37 -> 其中，同塔省约有200家企业已恢复活动。 | C36: =Du_lieu_goc!D37 -> Trong đó, riêng tỉnh Đồng Tháp, hiện có hơn 200 doanh nghiệp đã dần sản xuất trở lại. | D36: Trong đó, tỉnh Đồng Tháp có khoảng 200 doanh nghiệp đã hoạt động trở lại. | E36: Trong đó, khoảng 200 doanh nghiệp ở tỉnh Đồng Tháp đã hoạt động trở lại. | F36: Người 1 | G36: 88 | H36: 88 | I36: =I35 -> Người 2 | J36: 82 | K36: 82 | O36: 85 | P36: 85 | Q36: Hai người chấm lệch nhẹ (6 điểm). A và B tương đương (85 vs 85).
A37: 36 | B37: =Du_lieu_goc!C38 -> 落实第128号决议，谅山省为口岸商品通关活动安全、快速进行提供便利条件，确保实现防控疫情、发展经济“双胜利”。 | C37: =Du_lieu_goc!D38 -> Triển khai thực hiện Nghị quyết 128, tỉnh Lạng Sơn đã và đang tạo điều kiện thuận lợi để hoạt động thông quan hàng hóa qua cửa khẩu diễn ra an toàn, nhanh chóng, đảm bảo thực hiện mục tiêu kép vừa phòng chống dịch vừa phục hồi phát triển kinh tế. | D37: Để thực hiện Nghị quyết số 128, tỉnh Lạng Sơn đã tạo điều kiện thuận lợi cho hoạt động thông quan hàng hóa tại cửa khẩu diễn ra an toàn, nhanh chóng, đảm bảo đạt được "thắng lợi kép" trong công tác phòng chống dịch bệnh và phát triển kinh tế. | E37: Thực hiện Nghị quyết số 128, tỉnh Lạng Sơn tạo điều kiện thuận lợi cho hoạt động thông quan hàng hóa tại cảng diễn ra an toàn, nhanh chóng, bảo đảm “chiến thắng kép” trong công tác phòng, chống dịch bệnh và phát triển kinh tế. | F37: Người 1 | G37: 88 | H37: 72 | I37: =I36 -> Người 2 | J37: 80 | K37: 65 | M37: “Thông quan hàng hóa qua cửa khẩu” bị đổi thành “tại cảng”, làm sai địa điểm/loại cửa ngõ thông quan. | O37: 84 | P37: 68 | Q37: Hai người chấm lệch nhẹ (8 điểm). A vượt B rõ rệt (84 vs 68). Ghi nhận lỗi: B: “Thông quan hàng hóa qua cửa khẩu” bị đổi thành “tại cảng”, làm sai địa điểm/loại cửa ngõ thông quan.
A38: 37 | B38: =Du_lieu_goc!C39 -> 交通运输部副部长黎庭寿说：“货运和客运是我部最主要的2个领域。 | C38: =Du_lieu_goc!D39 -> Thứ trưởng Lê Đình Thọ khẳng định: “Ngành giao thông có 2 lĩnh vực chính là: vận tải hàng hóa và vận tải hành khách. | D38: Thứ trưởng Bộ Giao thông Vận tải Lê Đình Thọ cho biết: "Vận tải hàng hóa và vận tải hành khách là hai lĩnh vực chính yếu nhất của Bộ chúng tôi." | E38: Thứ trưởng Bộ GTVT Lê Đình Thọ cho biết: “Vận tải hàng hóa và hành khách là hai lĩnh vực quan trọng nhất của Bộ chúng ta. | F38: Người 1 | G38: 92 | H38: 90 | I38: =I37 -> Người 2 | J38: 90 | K38: 76 | M38: Tham chiếu nói về hai lĩnh vực chính của ngành giao thông; bản dịch chuyển sang “Bộ chúng ta”, làm đổi chủ thể và thêm đại từ người nghe. | N38: [Thắc mắc gốc] Bản đối chiếu không nhắc thứ trưởng bộ gtvt → [Đối chiếu bản Trung] Đối chiếu không nhắc chức danh "Thứ trưởng Bộ GTVT" nhưng bản Trung có 交通运输部副部长 → A/B đúng, đối chiếu lược bỏ. | O38: 91 | P38: 83 | Q38: Hai người chấm lệch nhẹ (14 điểm). Ghi nhận lỗi: A: Bản đối chiếu không nhắc thứ trưởng bộ gtvt | B: Tham chiếu nói về hai lĩnh vực chính của ngành giao thông; bản dịch chuyển sang “Bộ chúng ta”, làm đổi chủ thể và thêm đại từ người nghe.
A39: 38 | B39: =Du_lieu_goc!C40 -> 现在落实第128号决议，我们将审视、颁布新规定，确保符合决议目的、要求及卫生部相关防疫规定。 | C39: =Du_lieu_goc!D40 -> Khi triển khai Nghị quyết 128, chúng tôi rà soát, ban hành quy định mới để phù hợp với mục đích yêu cầu, đặc biệt là quy định mới của Bộ y tế. | D39: Hiện tại, để thực hiện Nghị quyết số 128, chúng tôi sẽ xem xét và ban hành các quy định mới, đảm bảo tuân thủ mục đích, yêu cầu của nghị quyết cũng như các quy định phòng chống dịch bệnh liên quan của Bộ Y tế. | E39: Nay để thực hiện Nghị quyết số 128, chúng ta sẽ rà soát, ban hành các quy định mới bảo đảm đúng mục đích, yêu cầu của Nghị quyết và các quy định phòng chống dịch có liên quan của Bộ Y tế. | F39: Người 1 | G39: 88 | H39: 88 | I39: =I38 -> Người 2 | J39: 78 | K39: 72 | L39: Tham chiếu mô tả việc rà soát, ban hành ở hiện tại và nhấn mạnh quy định mới của Bộ Y tế; bản dịch chuyển sang “sẽ” và làm mờ điểm nhấn này. | M39: Bản dịch chuyển “chúng tôi rà soát, ban hành” thành “chúng ta sẽ”, vừa đổi đại từ vừa đổi thời của hành động. | O39: 83 | P39: 80 | Q39: LỆCH LỚN 16 điểm giữa chấm chính và chấm chéo — cần rà lại. A và B tương đương (83 vs 80). Ghi nhận lỗi: A: Tham chiếu mô tả việc rà soát, ban hành ở hiện tại và nhấn mạnh quy định mới của Bộ Y tế; bản dịch chuyển sang “sẽ” và làm mờ điểm nhấn này. | B: Bản dịch chuyển “chúng tôi rà soát, ban hành” thành “chúng ta sẽ”, vừa đổi đại từ vừa đổi thời của hành động.
A40: 39 | B40: =Du_lieu_goc!C41 -> 巴地头顿省人民委员会副主席陈文俊表示，该省正逐步从防控疫情状态转为安全适应状态。 | C40: =Du_lieu_goc!D41 -> Theo ông Trần Văn Tuấn, Phó Chủ tịch UBND tỉnh Bà Rịa – Vũng Tàu, tỉnh đang chuyển trang thái từ chống dịch sang phòng dịch và thích ứng an toàn. | D40: Phó Chủ tịch Ủy ban Nhân dân tỉnh Bà Rịa - Vũng Tàu, ông Trần Văn Tuấn, cho biết tỉnh đang dần chuyển từ trạng thái kiểm soát dịch bệnh sang trạng thái thích ứng an toàn. | E40: Ông Trần Văn Tuấn, Phó Chủ tịch UBND tỉnh Bà Rịa-Vũng Tàu, cho biết tỉnh đang dần chuyển từ trạng thái phòng, chống dịch sang trạng thái thích ứng an toàn. | F40: Người 1 | G40: 90 | H40: 90 | I40: =I39 -> Người 2 | J40: 78 | K40: 80 | O40: 84 | P40: 85 | Q40: Hai người chấm lệch nhẹ (12 điểm). A và B tương đương (84 vs 85).
...
